# 예외처리

- 컴파일 에러 : 컴파일 시에 발생하는 에러
- 런타임 에러 : 실행 시에 발생하는 에러
- 논리적 에러 : 실행은 되지만 의도와 다르게 동작하는 것

### 예외 클래스의 계층 구조

자바에서는 실행 시 발생할 수 있는 오류를 클래스로 정의한다. 

![Untitled](https://user-images.githubusercontent.com/75190035/154838107-f5b557cc-49db-42f3-982b-755cda62324a.png)

- 모든 예외의 최고 조상은 Exception 클래스다.
- 자바의 예외는 두 그룹으로 나뉜다.
    1. Exception 클래스와 그 자손들(RuntimeException과 자손들 제외)
        - 사용자의 실수와 같은 외적인 요인에 의해 발생하는 예외
            - 입력 데이터 형식 오류 등
        - 예외 처리를 해주지 않으면 컴파일 조자 되지 않는다.
            - 컴파일러가 예외처리를 확인하는 예외를 **checked 예외 라고함**
    2. RuntimeException 클래스와 그 자손들
        - 프로그래머의 실수로 발생하는 예외
            - 배열의 범위를 벗어남, 클래스간 형변환 오류 등
        - 프로그래머의 실수에 의해 발생하는 에러임으로 예외처리를 강제하지 않는다.
            - 컴파일러가 예외처리를 확인하지 않는 예외를 **unchecked 예외 라고함**

### 예외 처리 try-catch 문

**예외 처리**

- 정의 : 프로그램 실행 시 발생할 수 있는 예외에 대비한 코드를 작성하는 것
- 목적 : 프로그램의 비정상 종료를 막고, 정상적인 실행 상태를 유지하는 것
- 예외를 처리하지 못하면, 프로그램은 비정상적으로 종료되며, 처리되지 못한 예외는 JVM의 예외처리기(UncaughtExceptionHandler)가 받아서 예외의 원인을 화면에 출력한다.
- try-catch문의 구조

```java
try{
	//예외 발생 가능성이 있는 코드
} catch (Exception1 e) {
	//예외 발생 시 이를 처리하기 위한 코드(Exception1)
} catch (Exception2 e) {
}
```

try 블럭, catch 블럭에 또 다른 try-catch 문이 포함될 수 있다.

catch 블럭에 선언된 변수는 catch블럭 내에서만 유효하기 때문에, 위의 모든 catch블럭에 같은 이름의 참조 변수 사용이 가능하다.

### try-catch문 흐름

- try블럭 내에서 예외가 발생
    1. 발생한 예외와 일치하는 catch블럭을 확인
    2. 일치하는 catch 블럭을 찾으면, 해당 블럭을 실행하고 전체 try-catch문을 빠져나가 그 다음 문장을 계속 수행한다.
        - 만약 같은 예외를 찾지 못하면, 예외는 처리되지 않는다.
- try블럭 내에서 예외가 발생하지 않은 경우
    1. catch블럭을 거치지 않고 그 다음 문장을 계속 수행
- catch 블럭의 흐름
    1. 예외가 발생하면, 발생한 예외에 해당하는 클래스의 인스턴스가 만들어진다.
    2. 첫번째 catch블럭 부터 차례로 내려가며 `instanceOf()` 연산자를 이용해 선언된 참조변수와 생성된 인스턴스를 검사한다.
    3. 검사 결과가 `true` 인 블럭을 찾게되면, 블럭에 있는 문장을 실행한 후 try-catch문을 빠져나가고, 검사 결과 일치하는 블럭을 찾지 못하면, 예외는 처리되지 않는다.

**printStackTrace(), getMessage()**

예외 발생시 생성되는 예외 클래스의 인스턴스에는 예외에 대한 정보가 담겨있다.

- `printStackTrace()` : 예외발생 당시 호출 스택(Call Stack)에 있었던 메서드의 정보와 예외 메시지를 화면에 출력
- `getMessage()` : 발생한 예외클래스의 인스턴스에 저장된 메시지를 얻을 수 있다.

**멀티 catch블럭**

JDK 1.7부터 여러 catch 블럭을 `|` 기호를 이용해서, 하나의 catch블럭으로 합칠 수 있다.(멀티 catch블럭)

```java
//일반 try-catch문
try{
	...
} catch(Exception1 e){
	e.printStackTrace();
} catch(Exception2 e){
	e.printStackTrace();
}

//멀티 catch블럭
try{
	...
} catch(Exception1 | Exception2 e){
	e.printStackTrace();
	e.methodA(); //에러. Exception1에 선언된 메서드는 호출 불가.
}
```

- `|` 로 연결된 예외클래스가 서로 상속관계에 있다면, 컴파일 에러가 발생한다. 두 예외클래스가 상속관계에 있다면 조상 클래스만 써주는 것과 동일하기 때문에 제거하라는 의미에서 에러가 발생하는 것이다.
- 멀티 catch블럭 내에서는 실제로 어떤 예외가 발생했는지 알 수 없다. 그래서 참조변수 `e` 로 공통 분모인 조상 예외 클래스에 선언된 멤버만 사용할 수 있다.
    - 필요하다면 `instanceOf` 로 어떤 예외가 발생했는지 확인하고, 개별적으로 처리할 수 있다.
- 멀티 catch 블럭에 선언된 참조변수는 상수이므로 값을 변경할 수 없다.

**예외 발생시키기**

`throw` 를 사용해서 고의로 예외를 발생시킬 수 있다.

1. 발생 시키려는 예외의 클래스의 객체를 만든다.
    - 이때, 생성자에 `String` 을 넣어주면, 이 메시지가 예외 메시지로 저장된다.
        - `getMessage()` 를 이용해서 얻을 수 있다.
2. 키워드 `throw`를 이용해서 예외를 발생시킨다.

### 메서드에 예외 선언

예외를 처리하는 방법에는 try-catch문을 사용하는 것 이외에, 예외를 메서드에 선언하는 방법이 있다.

```java
void method throws Exception1, Exception2{
	...
}
```

- 메서드 선언부만 봐도 메서드 사용을 위해 어떤 예외처리가 필요한지 알 수 있다.
- 사실 throws에 명시하는 것은 예외를 처리하는 것이 아니라, 자신을 호출한 메서드에게 예외를 **전달**해 예외 처리를 떠맡기는 것이다.
    - 예외를 전달받은 메서드가 또다시 자신을 호출한 메서드에게 전달할 수 있으며, 마지막에 있는 메서드에서도 예외가 처리되지 않으면 종료된다.

### finally블럭

finally블럭은 예외의 발생여부에 상관없이 실행되어야 할 코드를 포함시킬 목적으로 사용된다.

```java
try{
} catch(Exception e){
} finally{
	...
}
```

- 예외 발생: try → catch → finally 순서로 실행
- 정상 동작: try → finally
- 만약 try블럭이나 catch블럭에서 `return` 문이 실행되는 경우에는 finally블럭이 실행되고 `return` 문이 실행된다.

### 예외 되던지기

한 메서드에서 발생할 수 있는 예외가 여럿인 경우, 몇개는 try-catch문을 통해서 처리하고, 나머지는 호출한 메서드에서 처리하도록 하는 것이다.

예외가 발생할 가능성이 있는 메서드에서 try-catch문을 사용해서 예외를 처리해주고, throw문을 사요해 예외를 다시 발생시켜 호출한 메서드에 전달한다.

```java
class Ex{
	public static void main(String[] args){
		try{
			method1();
		} catch (Exception e){
			System.out.println("main메서드에서 예외가 처리");
		}
	}
	static void method1() thorows Exception{
		try{
			throw new Exception();
		} catch (Exception e){
			System.out.println("method1 메서드에서 예외가 처리");
			throw e;
		}
	}
}
```

### 연결된 예외

한 예외 A가 다른 예외 B를 발생시킨다면 A를 B의 원인 예외라고 한다.

- `Throwable initCause(Throwable cause)` : 지정한 예외를 원인 예외로 등록
- `Throwable getCause()` : 원인 예외를 반환

이렇게 하는 이유는 예외를 하나의 큰 분류의 예외로 묶어서 다루기 위해서다. 또한 checked예외를 unckecked예외로 바꾸도록 할 수 있다.

```java
//일반 예외발생
static void startInstall() throws SpaceException, MemoryException{
	if (!enoughSpace())
		throw new SpaceException("설치 공간 부족");
	if (!enoughMemory())
		throw new MemoryException("메모리 부족");
}

//연결된 예외
static void startInstall() throws SpaceException, MemoryException{
	if (!enoughSpace())
		throw new SpaceException("설치 공간 부족");
	if (!enoughMemory())
		throw new RuntimeException(throw new MemoryException("메모리 부족"));
		//checked -> unchecked
}
```
